Workbook

Sheet Painel
A1: GCA · GUERRILHEIROS
A2: Painel das squads regionais de comunicação · Piauí
A5: 1º turno | B5: 46299 | C5: =IF($B$5="","",MAX(0,$B$5-TODAY())) -> 19 | D5: dias para a eleição
A6: Meta por squad (dia) | B6: 10 | C6: =B6*MAX(1,COUNTA(Listas!$A$5:$A$64)) -> 60 | D6: meta total por dia
A7: Ver período | B7: Últimos 30 dias | C7: De | E7: até | G7: =IF('Por dia'!$S$5>=DATE(2099,1,1),"tudo o que está cadastrado","de "&TEXT('Por dia'!$R$5,"dd/mm/yyyy")&" a "&TEXT('Por dia'!$S$5,"dd/mm/yyyy")) -> de 17/08/2026 a 15/09/2026
A8: HOJE
A9: Concluídos hoje | B9: Meta do dia | C9: Atingimento | D9: Cadastrados hoje | E9: Repercussões hoje | F9: Vencem hoje
A10: =COUNTIFS(Ações!$N$6:$N$404,TODAY(),Ações!$O$6:$O$404,"Sim") -> 0 | B10: =$C$6 -> 60 | C10: =IF($C$6=0,"-",COUNTIFS(Ações!$N$6:$N$404,TODAY(),Ações!$O$6:$O$404,"Sim")/$C$6) -> 0 | D10: =COUNTIF(Ações!$A$6:$A$404,TODAY()) -> 0 | E10: =COUNTIF(Repercussão!$A$6:$A$304,TODAY()) -> 0 | F10: =COUNTIFS(Ações!$M$6:$M$404,TODAY(),Ações!$O$6:$O$404,"Não") -> 0
A12: NO PERÍODO ESCOLHIDO | E12: muda tudo daqui para baixo conforme o filtro do topo
A13: Ações | B13: Em produção | C13: Em aprovação | D13: Concluídos | E13: Atrasados | F13: Stand-by | G13: Checklist OK | H13: Audiovisuais
A14: =COUNTIFS(Ações!$A$6:$A$404,">="&'Por dia'!$R$5,Ações!$A$6:$A$404,"<="&'Por dia'!$S$5) -> 0 | B14: =COUNTIFS(Ações!$A$6:$A$404,">="&'Por dia'!$R$5,Ações!$A$6:$A$404,"<="&'Por dia'!$S$5,Ações!$K$6:$K$404,"Em produção") -> 0 | C14: =COUNTIFS(Ações!$A$6:$A$404,">="&'Por dia'!$R$5,Ações!$A$6:$A$404,"<="&'Por dia'!$S$5,Ações!$K$6:$K$404,"Em aprovação") -> 0 | D14: =COUNTIFS(Ações!$N$6:$N$404,">="&'Por dia'!$R$5,Ações!$N$6:$N$404,"<="&'Por dia'!$S$5,Ações!$O$6:$O$404,"Sim") -> 0 | E14: =COUNTIFS(Ações!$A$6:$A$404,">="&'Por dia'!$R$5,Ações!$A$6:$A$404,"<="&'Por dia'!$S$5,Ações!$P$6:$P$404,"Atrasada") -> 0 | F14: =COUNTIFS(Ações!$A$6:$A$404,">="&'Por dia'!$R$5,Ações!$A$6:$A$404,"<="&'Por dia'!$S$5,Ações!$K$6:$K$404,"Stand-by") -> 0 | G14: =COUNTIFS(Ações!$A$6:$A$404,">="&'Por dia'!$R$5,Ações!$A$6:$A$404,"<="&'Por dia'!$S$5,Ações!$Q$6:$Q$404,"OK") -> 0 | H14: =COUNTIFS(Ações!$A$6:$A$404,">="&'Por dia'!$R$5,Ações!$A$6:$A$404,"<="&'Por dia'!$S$5,Ações!$U$6:$U$404,"Sim") -> 0
A16: REPERCUSSÃO NO PERÍODO
A17: Registradas | B17: Alcance | C17: Interações | D17: Positivas | E17: Neutras | F17: Negativas
A18: =COUNTIFS(Repercussão!$A$6:$A$304,">="&'Por dia'!$R$5,Repercussão!$A$6:$A$304,"<="&'Por dia'!$S$5) -> 0 | B18: =SUMIFS(Repercussão!$G$6:$G$304,Repercussão!$A$6:$A$304,">="&'Por dia'!$R$5,Repercussão!$A$6:$A$304,"<="&'Por dia'!$S$5) -> 0 | C18: =SUMIFS(Repercussão!$H$6:$H$304,Repercussão!$A$6:$A$304,">="&'Por dia'!$R$5,Repercussão!$A$6:$A$304,"<="&'Por dia'!$S$5) -> 0 | D18: =COUNTIFS(Repercussão!$A$6:$A$304,">="&'Por dia'!$R$5,Repercussão!$A$6:$A$304,"<="&'Por dia'!$S$5,Repercussão!$I$6:$I$304,"Positiva") -> 0 | E18: =COUNTIFS(Repercussão!$A$6:$A$304,">="&'Por dia'!$R$5,Repercussão!$A$6:$A$304,"<="&'Por dia'!$S$5,Repercussão!$I$6:$I$304,"Neutra") -> 0 | F18: =COUNTIFS(Repercussão!$A$6:$A$304,">="&'Por dia'!$R$5,Repercussão!$A$6:$A$304,"<="&'Por dia'!$S$5,Repercussão!$I$6:$I$304,"Negativa") -> 0
A21: CONTEÚDOS CONCLUÍDOS POR DIA
A39: POR SQUAD
A40: Squad | B40: Ações | C40: Produção | D40: Aprovação | E40: Concluídos | F40: Atrasados | G40: Repercussões | H40: Produção visual
A41: =Listas!A5 -> Litoral | B41: =COUNTIFS(Ações!$B$6:$B$404,$A41,Ações!$A$6:$A$404,">="&'Por dia'!$R$5,Ações!$A$6:$A$404,"<="&'Por dia'!$S$5) -> 0 | C41: =COUNTIFS(Ações!$B$6:$B$404,$A41,Ações!$A$6:$A$404,">="&'Por dia'!$R$5,Ações!$A$6:$A$404,"<="&'Por dia'!$S$5,Ações!$K$6:$K$404,"Em produção") -> 0 | D41: =COUNTIFS(Ações!$B$6:$B$404,$A41,Ações!$A$6:$A$404,">="&'Por dia'!$R$5,Ações!$A$6:$A$404,"<="&'Por dia'!$S$5,Ações!$K$6:$K$404,"Em aprovação") -> 0 | E41: =COUNTIFS(Ações!$B$6:$B$404,$A41,Ações!$N$6:$N$404,">="&'Por dia'!$R$5,Ações!$N$6:$N$404,"<="&'Por dia'!$S$5,Ações!$O$6:$O$404,"Sim") -> 0 | F41: =COUNTIFS(Ações!$B$6:$B$404,$A41,Ações!$A$6:$A$404,">="&'Por dia'!$R$5,Ações!$A$6:$A$404,"<="&'Por dia'!$S$5,Ações!$P$6:$P$404,"Atrasada") -> 0 | G41: =COUNTIFS(Repercussão!$B$6:$B$304,$A41,Repercussão!$A$6:$A$304,">="&'Por dia'!$R$5,Repercussão!$A$6:$A$304,"<="&'Por dia'!$S$5) -> 0 | H41: =IF($E41=0,"",REPT("|",MIN(22,$E41)))
A42: =Listas!A6 -> Meio Norte | B42: =COUNTIFS(Ações!$B$6:$B$404,$A42,Ações!$A$6:$A$404,">="&'Por dia'!$R$5,Ações!$A$6:$A$404,"<="&'Por dia'!$S$5) -> 0 | C42: =COUNTIFS(Ações!$B$6:$B$404,$A42,Ações!$A$6:$A$404,">="&'Por dia'!$R$5,Ações!$A$6:$A$404,"<="&'Por dia'!$S$5,Ações!$K$6:$K$404,"Em produção") -> 0 | D42: =COUNTIFS(Ações!$B$6:$B$404,$A42,Ações!$A$6:$A$404,">="&'Por dia'!$R$5,Ações!$A$6:$A$404,"<="&'Por dia'!$S$5,Ações!$K$6:$K$404,"Em aprovação") -> 0 | E42: =COUNTIFS(Ações!$B$6:$B$404,$A42,Ações!$N$6:$N$404,">="&'Por dia'!$R$5,Ações!$N$6:$N$404,"<="&'Por dia'!$S$5,Ações!$O$6:$O$404,"Sim") -> 0 | F42: =COUNTIFS(Ações!$B$6:$B$404,$A42,Ações!$A$6:$A$404,">="&'Por dia'!$R$5,Ações!$A$6:$A$404,"<="&'Por dia'!$S$5,Ações!$P$6:$P$404,"Atrasada") -> 0 | G42: =COUNTIFS(Repercussão!$B$6:$B$304,$A42,Repercussão!$A$6:$A$304,">="&'Por dia'!$R$5,Repercussão!$A$6:$A$304,"<="&'Por dia'!$S$5) -> 0 | H42: =IF($E42=0,"",REPT("|",MIN(22,$E42)))
A43: =Listas!A7 -> Cerrado | B43: =COUNTIFS(Ações!$B$6:$B$404,$A43,Ações!$A$6:$A$404,">="&'Por dia'!$R$5,Ações!$A$6:$A$404,"<="&'Por dia'!$S$5) -> 0 | C43: =COUNTIFS(Ações!$B$6:$B$404,$A43,Ações!$A$6:$A$404,">="&'Por dia'!$R$5,Ações!$A$6:$A$404,"<="&'Por dia'!$S$5,Ações!$K$6:$K$404,"Em produção") -> 0 | D43: =COUNTIFS(Ações!$B$6:$B$404,$A43,Ações!$A$6:$A$404,">="&'Por dia'!$R$5,Ações!$A$6:$A$404,"<="&'Por dia'!$S$5,Ações!$K$6:$K$404,"Em aprovação") -> 0 | E43: =COUNTIFS(Ações!$B$6:$B$404,$A43,Ações!$N$6:$N$404,">="&'Por dia'!$R$5,Ações!$N$6:$N$404,"<="&'Por dia'!$S$5,Ações!$O$6:$O$404,"Sim") -> 0 | F43: =COUNTIFS(Ações!$B$6:$B$404,$A43,Ações!$A$6:$A$404,">="&'Por dia'!$R$5,Ações!$A$6:$A$404,"<="&'Por dia'!$S$5,Ações!$P$6:$P$404,"Atrasada") -> 0 | G43: =COUNTIFS(Repercussão!$B$6:$B$304,$A43,Repercussão!$A$6:$A$304,">="&'Por dia'!$R$5,Repercussão!$A$6:$A$304,"<="&'Por dia'!$S$5) -> 0 | H43: =IF($E43=0,"",REPT("|",MIN(22,$E43)))
A44: =Listas!A8 -> Semiárido Norte | B44: =COUNTIFS(Ações!$B$6:$B$404,$A44,Ações!$A$6:$A$404,">="&'Por dia'!$R$5,Ações!$A$6:$A$404,"<="&'Por dia'!$S$5) -> 0 | C44: =COUNTIFS(Ações!$B$6:$B$404,$A44,Ações!$A$6:$A$404,">="&'Por dia'!$R$5,Ações!$A$6:$A$404,"<="&'Por dia'!$S$5,Ações!$K$6:$K$404,"Em produção") -> 0 | D44: =COUNTIFS(Ações!$B$6:$B$404,$A44,Ações!$A$6:$A$404,">="&'Por dia'!$R$5,Ações!$A$6:$A$404,"<="&'Por dia'!$S$5,Ações!$K$6:$K$404,"Em aprovação") -> 0 | E44: =COUNTIFS(Ações!$B$6:$B$404,$A44,Ações!$N$6:$N$404,">="&'Por dia'!$R$5,Ações!$N$6:$N$404,"<="&'Por dia'!$S$5,Ações!$O$6:$O$404,"Sim") -> 0 | F44: =COUNTIFS(Ações!$B$6:$B$404,$A44,Ações!$A$6:$A$404,">="&'Por dia'!$R$5,Ações!$A$6:$A$404,"<="&'Por dia'!$S$5,Ações!$P$6:$P$404,"Atrasada") -> 0 | G44: =COUNTIFS(Repercussão!$B$6:$B$304,$A44,Repercussão!$A$6:$A$304,">="&'Por dia'!$R$5,Repercussão!$A$6:$A$304,"<="&'Por dia'!$S$5) -> 0 | H44: =IF($E44=0,"",REPT("|",MIN(22,$E44)))
A45: =Listas!A9 -> Semiárido Sul | B45: =COUNTIFS(Ações!$B$6:$B$404,$A45,Ações!$A$6:$A$404,">="&'Por dia'!$R$5,Ações!$A$6:$A$404,"<="&'Por dia'!$S$5) -> 0 | C45: =COUNTIFS(Ações!$B$6:$B$404,$A45,Ações!$A$6:$A$404,">="&'Por dia'!$R$5,Ações!$A$6:$A$404,"<="&'Por dia'!$S$5,Ações!$K$6:$K$404,"Em produção") -> 0 | D45: =COUNTIFS(Ações!$B$6:$B$404,$A45,Ações!$A$6:$A$404,">="&'Por dia'!$R$5,Ações!$A$6:$A$404,"<="&'Por dia'!$S$5,Ações!$K$6:$K$404,"Em aprovação") -> 0 | E45: =COUNTIFS(Ações!$B$6:$B$404,$A45,Ações!$N$6:$N$404,">="&'Por dia'!$R$5,Ações!$N$6:$N$404,"<="&'Por dia'!$S$5,Ações!$O$6:$O$404,"Sim") -> 0 | F45: =COUNTIFS(Ações!$B$6:$B$404,$A45,Ações!$A$6:$A$404,">="&'Por dia'!$R$5,Ações!$A$6:$A$404,"<="&'Por dia'!$S$5,Ações!$P$6:$P$404,"Atrasada") -> 0 | G45: =COUNTIFS(Repercussão!$B$6:$B$304,$A45,Repercussão!$A$6:$A$304,">="&'Por dia'!$R$5,Repercussão!$A$6:$A$304,"<="&'Por dia'!$S$5) -> 0 | H45: =IF($E45=0,"",REPT("|",MIN(22,$E45)))
A46: =Listas!A10 -> Águas de Teresina | B46: =COUNTIFS(Ações!$B$6:$B$404,$A46,Ações!$A$6:$A$404,">="&'Por dia'!$R$5,Ações!$A$6:$A$404,"<="&'Por dia'!$S$5) -> 0 | C46: =COUNTIFS(Ações!$B$6:$B$404,$A46,Ações!$A$6:$A$404,">="&'Por dia'!$R$5,Ações!$A$6:$A$404,"<="&'Por dia'!$S$5,Ações!$K$6:$K$404,"Em produção") -> 0 | D46: =COUNTIFS(Ações!$B$6:$B$404,$A46,Ações!$A$6:$A$404,">="&'Por dia'!$R$5,Ações!$A$6:$A$404,"<="&'Por dia'!$S$5,Ações!$K$6:$K$404,"Em aprovação") -> 0 | E46: =COUNTIFS(Ações!$B$6:$B$404,$A46,Ações!$N$6:$N$404,">="&'Por dia'!$R$5,Ações!$N$6:$N$404,"<="&'Por dia'!$S$5,Ações!$O$6:$O$404,"Sim") -> 0 | F46: =COUNTIFS(Ações!$B$6:$B$404,$A46,Ações!$A$6:$A$404,">="&'Por dia'!$R$5,Ações!$A$6:$A$404,"<="&'Por dia'!$S$5,Ações!$P$6:$P$404,"Atrasada") -> 0 | G46: =COUNTIFS(Repercussão!$B$6:$B$304,$A46,Repercussão!$A$6:$A$304,">="&'Por dia'!$R$5,Repercussão!$A$6:$A$304,"<="&'Por dia'!$S$5) -> 0 | H46: =IF($E46=0,"",REPT("|",MIN(22,$E46)))
A47: TOTAL | B47: =SUM(B41:B46) -> 0 | C47: =SUM(C41:C46) -> 0 | D47: =SUM(D41:D46) -> 0 | E47: =SUM(E41:E46) -> 0 | F47: =SUM(F41:F46) -> 0 | G47: =SUM(G41:G46) -> 0
A49: POR ANALISTA
A50: Analista | B50: Ações | C50: Produção | D50: Concluídos | E50: Atrasados | F50: Checklist OK | G50: Repercussões | H50: Produção visual
A51: =Listas!B5 -> Luiz Fernando de Sousa Gonzaga | B51: =COUNTIFS(Ações!$C$6:$C$404,$A51,Ações!$A$6:$A$404,">="&'Por dia'!$R$5,Ações!$A$6:$A$404,"<="&'Por dia'!$S$5) -> 0 | C51: =COUNTIFS(Ações!$C$6:$C$404,$A51,Ações!$A$6:$A$404,">="&'Por dia'!$R$5,Ações!$A$6:$A$404,"<="&'Por dia'!$S$5,Ações!$K$6:$K$404,"Em produção") -> 0 | D51: =COUNTIFS(Ações!$C$6:$C$404,$A51,Ações!$N$6:$N$404,">="&'Por dia'!$R$5,Ações!$N$6:$N$404,"<="&'Por dia'!$S$5,Ações!$O$6:$O$404,"Sim") -> 0 | E51: =COUNTIFS(Ações!$C$6:$C$404,$A51,Ações!$A$6:$A$404,">="&'Por dia'!$R$5,Ações!$A$6:$A$404,"<="&'Por dia'!$S$5,Ações!$P$6:$P$404,"Atrasada") -> 0 | F51: =COUNTIFS(Ações!$C$6:$C$404,$A51,Ações!$A$6:$A$404,">="&'Por dia'!$R$5,Ações!$A$6:$A$404,"<="&'Por dia'!$S$5,Ações!$Q$6:$Q$404,"OK") -> 0 | G51: =COUNTIFS(Repercussão!$K$6:$K$304,$A51,Repercussão!$A$6:$A$304,">="&'Por dia'!$R$5,Repercussão!$A$6:$A$304,"<="&'Por dia'!$S$5) -> 0 | H51: =IF($D51=0,"",REPT("|",MIN(22,$D51)))
A52: =Listas!B6 -> Bruno (SA Propaganda) | B52: =COUNTIFS(Ações!$C$6:$C$404,$A52,Ações!$A$6:$A$404,">="&'Por dia'!$R$5,Ações!$A$6:$A$404,"<="&'Por dia'!$S$5) -> 0 | C52: =COUNTIFS(Ações!$C$6:$C$404,$A52,Ações!$A$6:$A$404,">="&'Por dia'!$R$5,Ações!$A$6:$A$404,"<="&'Por dia'!$S$5,Ações!$K$6:$K$404,"Em produção") -> 0 | D52: =COUNTIFS(Ações!$C$6:$C$404,$A52,Ações!$N$6:$N$404,">="&'Por dia'!$R$5,Ações!$N$6:$N$404,"<="&'Por dia'!$S$5,Ações!$O$6:$O$404,"Sim") -> 0 | E52: =COUNTIFS(Ações!$C$6:$C$404,$A52,Ações!$A$6:$A$404,">="&'Por dia'!$R$5,Ações!$A$6:$A$404,"<="&'Por dia'!$S$5,Ações!$P$6:$P$404,"Atrasada") -> 0 | F52: =COUNTIFS(Ações!$C$6:$C$404,$A52,Ações!$A$6:$A$404,">="&'Por dia'!$R$5,Ações!$A$6:$A$404,"<="&'Por dia'!$S$5,Ações!$Q$6:$Q$404,"OK") -> 0 | G52: =COUNTIFS(Repercussão!$K$6:$K$304,$A52,Repercussão!$A$6:$A$304,">="&'Por dia'!$R$5,Repercussão!$A$6:$A$304,"<="&'Por dia'!$S$5) -> 0 | H52: =IF($D52=0,"",REPT("|",MIN(22,$D52)))
A53: =Listas!B7 -> Daniel Saturnino (Ícone) | B53: =COUNTIFS(Ações!$C$6:$C$404,$A53,Ações!$A$6:$A$404,">="&'Por dia'!$R$5,Ações!$A$6:$A$404,"<="&'Por dia'!$S$5) -> 0 | C53: =COUNTIFS(Ações!$C$6:$C$404,$A53,Ações!$A$6:$A$404,">="&'Por dia'!$R$5,Ações!$A$6:$A$404,"<="&'Por dia'!$S$5,Ações!$K$6:$K$404,"Em produção") -> 0 | D53: =COUNTIFS(Ações!$C$6:$C$404,$A53,Ações!$N$6:$N$404,">="&'Por dia'!$R$5,Ações!$N$6:$N$404,"<="&'Por dia'!$S$5,Ações!$O$6:$O$404,"Sim") -> 0 | E53: =COUNTIFS(Ações!$C$6:$C$404,$A53,Ações!$A$6:$A$404,">="&'Por dia'!$R$5,Ações!$A$6:$A$404,"<="&'Por dia'!$S$5,Ações!$P$6:$P$404,"Atrasada") -> 0 | F53: =COUNTIFS(Ações!$C$6:$C$404,$A53,Ações!$A$6:$A$404,">="&'Por dia'!$R$5,Ações!$A$6:$A$404,"<="&'Por dia'!$S$5,Ações!$Q$6:$Q$404,"OK") -> 0 | G53: =COUNTIFS(Repercussão!$K$6:$K$304,$A53,Repercussão!$A$6:$A$304,">="&'Por dia'!$R$5,Repercussão!$A$6:$A$304,"<="&'Por dia'!$S$5) -> 0 | H53: =IF($D53=0,"",REPT("|",MIN(22,$D53)))
A54: =Listas!B8 -> Ana Isabel Monteiro de Sousa | B54: =COUNTIFS(Ações!$C$6:$C$404,$A54,Ações!$A$6:$A$404,">="&'Por dia'!$R$5,Ações!$A$6:$A$404,"<="&'Por dia'!$S$5) -> 0 | C54: =COUNTIFS(Ações!$C$6:$C$404,$A54,Ações!$A$6:$A$404,">="&'Por dia'!$R$5,Ações!$A$6:$A$404,"<="&'Por dia'!$S$5,Ações!$K$6:$K$404,"Em produção") -> 0 | D54: =COUNTIFS(Ações!$C$6:$C$404,$A54,Ações!$N$6:$N$404,">="&'Por dia'!$R$5,Ações!$N$6:$N$404,"<="&'Por dia'!$S$5,Ações!$O$6:$O$404,"Sim") -> 0 | E54: =COUNTIFS(Ações!$C$6:$C$404,$A54,Ações!$A$6:$A$404,">="&'Por dia'!$R$5,Ações!$A$6:$A$404,"<="&'Por dia'!$S$5,Ações!$P$6:$P$404,"Atrasada") -> 0 | F54: =COUNTIFS(Ações!$C$6:$C$404,$A54,Ações!$A$6:$A$404,">="&'Por dia'!$R$5,Ações!$A$6:$A$404,"<="&'Por dia'!$S$5,Ações!$Q$6:$Q$404,"OK") -> 0 | G54: =COUNTIFS(Repercussão!$K$6:$K$304,$A54,Repercussão!$A$6:$A$304,">="&'Por dia'!$R$5,Repercussão!$A$6:$A$304,"<="&'Por dia'!$S$5) -> 0 | H54: =IF($D54=0,"",REPT("|",MIN(22,$D54)))
A55: =Listas!B9 -> Ivana Machado Vasconcelos | B55: =COUNTIFS(Ações!$C$6:$C$404,$A55,Ações!$A$6:$A$404,">="&'Por dia'!$R$5,Ações!$A$6:$A$404,"<="&'Por dia'!$S$5) -> 0 | C55: =COUNTIFS(Ações!$C$6:$C$404,$A55,Ações!$A$6:$A$404,">="&'Por dia'!$R$5,Ações!$A$6:$A$404,"<="&'Por dia'!$S$5,Ações!$K$6:$K$404,"Em produção") -> 0 | D55: =COUNTIFS(Ações!$C$6:$C$404,$A55,Ações!$N$6:$N$404,">="&'Por dia'!$R$5,Ações!$N$6:$N$404,"<="&'Por dia'!$S$5,Ações!$O$6:$O$404,"Sim") -> 0 | E55: =COUNTIFS(Ações!$C$6:$C$404,$A55,Ações!$A$6:$A$404,">="&'Por dia'!$R$5,Ações!$A$6:$A$404,"<="&'Por dia'!$S$5,Ações!$P$6:$P$404,"Atrasada") -> 0 | F55: =COUNTIFS(Ações!$C$6:$C$404,$A55,Ações!$A$6:$A$404,">="&'Por dia'!$R$5,Ações!$A$6:$A$404,"<="&'Por dia'!$S$5,Ações!$Q$6:$Q$404,"OK") -> 0 | G55: =COUNTIFS(Repercussão!$K$6:$K$304,$A55,Repercussão!$A$6:$A$304,">="&'Por dia'!$R$5,Repercussão!$A$6:$A$304,"<="&'Por dia'!$S$5) -> 0 | H55: =IF($D55=0,"",REPT("|",MIN(22,$D55)))
A56: =Listas!B10 -> Phillipe Xadai (Conecta Piauí) | B56: =COUNTIFS(Ações!$C$6:$C$404,$A56,Ações!$A$6:$A$404,">="&'Por dia'!$R$5,Ações!$A$6:$A$404,"<="&'Por dia'!$S$5) -> 0 | C56: =COUNTIFS(Ações!$C$6:$C$404,$A56,Ações!$A$6:$A$404,">="&'Por dia'!$R$5,Ações!$A$6:$A$404,"<="&'Por dia'!$S$5,Ações!$K$6:$K$404,"Em produção") -> 0 | D56: =COUNTIFS(Ações!$C$6:$C$404,$A56,Ações!$N$6:$N$404,">="&'Por dia'!$R$5,Ações!$N$6:$N$404,"<="&'Por dia'!$S$5,Ações!$O$6:$O$404,"Sim") -> 0 | E56: =COUNTIFS(Ações!$C$6:$C$404,$A56,Ações!$A$6:$A$404,">="&'Por dia'!$R$5,Ações!$A$6:$A$404,"<="&'Por dia'!$S$5,Ações!$P$6:$P$404,"Atrasada") -> 0 | F56: =COUNTIFS(Ações!$C$6:$C$404,$A56,Ações!$A$6:$A$404,">="&'Por dia'!$R$5,Ações!$A$6:$A$404,"<="&'Por dia'!$S$5,Ações!$Q$6:$Q$404,"OK") -> 0 | G56: =COUNTIFS(Repercussão!$K$6:$K$304,$A56,Repercussão!$A$6:$A$304,">="&'Por dia'!$R$5,Repercussão!$A$6:$A$304,"<="&'Por dia'!$S$5) -> 0 | H56: =IF($D56=0,"",REPT("|",MIN(22,$D56)))
A57: =Listas!B11 -> Maria Andreia Monteiro de Sousa | B57: =COUNTIFS(Ações!$C$6:$C$404,$A57,Ações!$A$6:$A$404,">="&'Por dia'!$R$5,Ações!$A$6:$A$404,"<="&'Por dia'!$S$5) -> 0 | C57: =COUNTIFS(Ações!$C$6:$C$404,$A57,Ações!$A$6:$A$404,">="&'Por dia'!$R$5,Ações!$A$6:$A$404,"<="&'Por dia'!$S$5,Ações!$K$6:$K$404,"Em produção") -> 0 | D57: =COUNTIFS(Ações!$C$6:$C$404,$A57,Ações!$N$6:$N$404,">="&'Por dia'!$R$5,Ações!$N$6:$N$404,"<="&'Por dia'!$S$5,Ações!$O$6:$O$404,"Sim") -> 0 | E57: =COUNTIFS(Ações!$C$6:$C$404,$A57,Ações!$A$6:$A$404,">="&'Por dia'!$R$5,Ações!$A$6:$A$404,"<="&'Por dia'!$S$5,Ações!$P$6:$P$404,"Atrasada") -> 0 | F57: =COUNTIFS(Ações!$C$6:$C$404,$A57,Ações!$A$6:$A$404,">="&'Por dia'!$R$5,Ações!$A$6:$A$404,"<="&'Por dia'!$S$5,Ações!$Q$6:$Q$404,"OK") -> 0 | G57: =COUNTIFS(Repercussão!$K$6:$K$304,$A57,Repercussão!$A$6:$A$304,">="&'Por dia'!$R$5,Repercussão!$A$6:$A$304,"<="&'Por dia'!$S$5) -> 0 | H57: =IF($D57=0,"",REPT("|",MIN(22,$D57)))
A58: =Listas!B12 -> Fernanda Messias de Carvalho | B58: =COUNTIFS(Ações!$C$6:$C$404,$A58,Ações!$A$6:$A$404,">="&'Por dia'!$R$5,Ações!$A$6:$A$404,"<="&'Por dia'!$S$5) -> 0 | C58: =COUNTIFS(Ações!$C$6:$C$404,$A58,Ações!$A$6:$A$404,">="&'Por dia'!$R$5,Ações!$A$6:$A$404,"<="&'Por dia'!$S$5,Ações!$K$6:$K$404,"Em produção") -> 0 | D58: =COUNTIFS(Ações!$C$6:$C$404,$A58,Ações!$N$6:$N$404,">="&'Por dia'!$R$5,Ações!$N$6:$N$404,"<="&'Por dia'!$S$5,Ações!$O$6:$O$404,"Sim") -> 0 | E58: =COUNTIFS(Ações!$C$6:$C$404,$A58,Ações!$A$6:$A$404,">="&'Por dia'!$R$5,Ações!$A$6:$A$404,"<="&'Por dia'!$S$5,Ações!$P$6:$P$404,"Atrasada") -> 0 | F58: =COUNTIFS(Ações!$C$6:$C$404,$A58,Ações!$A$6:$A$404,">="&'Por dia'!$R$5,Ações!$A$6:$A$404,"<="&'Por dia'!$S$5,Ações!$Q$6:$Q$404,"OK") -> 0 | G58: =COUNTIFS(Repercussão!$K$6:$K$304,$A58,Repercussão!$A$6:$A$304,">="&'Por dia'!$R$5,Repercussão!$A$6:$A$304,"<="&'Por dia'!$S$5) -> 0 | H58: =IF($D58=0,"",REPT("|",MIN(22,$D58)))
A59: =Listas!B13 -> Leonardo Costa (Conecta Piauí) | B59: =COUNTIFS(Ações!$C$6:$C$404,$A59,Ações!$A$6:$A$404,">="&'Por dia'!$R$5,Ações!$A$6:$A$404,"<="&'Por dia'!$S$5) -> 0 | C59: =COUNTIFS(Ações!$C$6:$C$404,$A59,Ações!$A$6:$A$404,">="&'Por dia'!$R$5,Ações!$A$6:$A$404,"<="&'Por dia'!$S$5,Ações!$K$6:$K$404,"Em produção") -> 0 | D59: =COUNTIFS(Ações!$C$6:$C$404,$A59,Ações!$N$6:$N$404,">="&'Por dia'!$R$5,Ações!$N$6:$N$404,"<="&'Por dia'!$S$5,Ações!$O$6:$O$404,"Sim") -> 0 | E59: =COUNTIFS(Ações!$C$6:$C$404,$A59,Ações!$A$6:$A$404,">="&'Por dia'!$R$5,Ações!$A$6:$A$404,"<="&'Por dia'!$S$5,Ações!$P$6:$P$404,"Atrasada") -> 0 | F59: =COUNTIFS(Ações!$C$6:$C$404,$A59,Ações!$A$6:$A$404,">="&'Por dia'!$R$5,Ações!$A$6:$A$404,"<="&'Por dia'!$S$5,Ações!$Q$6:$Q$404,"OK") -> 0 | G59: =COUNTIFS(Repercussão!$K$6:$K$304,$A59,Repercussão!$A$6:$A$304,">="&'Por dia'!$R$5,Repercussão!$A$6:$A$304,"<="&'Por dia'!$S$5) -> 0 | H59: =IF($D59=0,"",REPT("|",MIN(22,$D59)))
A60: =Listas!B14 -> Marta Soares Lima | B60: =COUNTIFS(Ações!$C$6:$C$404,$A60,Ações!$A$6:$A$404,">="&'Por dia'!$R$5,Ações!$A$6:$A$404,"<="&'Por dia'!$S$5) -> 0 | C60: =COUNTIFS(Ações!$C$6:$C$404,$A60,Ações!$A$6:$A$404,">="&'Por dia'!$R$5,Ações!$A$6:$A$404,"<="&'Por dia'!$S$5,Ações!$K$6:$K$404,"Em produção") -> 0 | D60: =COUNTIFS(Ações!$C$6:$C$404,$A60,Ações!$N$6:$N$404,">="&'Por dia'!$R$5,Ações!$N$6:$N$404,"<="&'Por dia'!$S$5,Ações!$O$6:$O$404,"Sim") -> 0 | E60: =COUNTIFS(Ações!$C$6:$C$404,$A60,Ações!$A$6:$A$404,">="&'Por dia'!$R$5,Ações!$A$6:$A$404,"<="&'Por dia'!$S$5,Ações!$P$6:$P$404,"Atrasada") -> 0 | F60: =COUNTIFS(Ações!$C$6:$C$404,$A60,Ações!$A$6:$A$404,">="&'Por dia'!$R$5,Ações!$A$6:$A$404,"<="&'Por dia'!$S$5,Ações!$Q$6:$Q$404,"OK") -> 0 | G60: =COUNTIFS(Repercussão!$K$6:$K$304,$A60,Repercussão!$A$6:$A$304,">="&'Por dia'!$R$5,Repercussão!$A$6:$A$304,"<="&'Por dia'!$S$5) -> 0 | H60: =IF($D60=0,"",REPT("|",MIN(22,$D60)))
A61: =Listas!B15 -> Thyago Felipe Alves da Costa | B61: =COUNTIFS(Ações!$C$6:$C$404,$A61,Ações!$A$6:$A$404,">="&'Por dia'!$R$5,Ações!$A$6:$A$404,"<="&'Por dia'!$S$5) -> 0 | C61: =COUNTIFS(Ações!$C$6:$C$404,$A61,Ações!$A$6:$A$404,">="&'Por dia'!$R$5,Ações!$A$6:$A$404,"<="&'Por dia'!$S$5,Ações!$K$6:$K$404,"Em produção") -> 0 | D61: =COUNTIFS(Ações!$C$6:$C$404,$A61,Ações!$N$6:$N$404,">="&'Por dia'!$R$5,Ações!$N$6:$N$404,"<="&'Por dia'!$S$5,Ações!$O$6:$O$404,"Sim") -> 0 | E61: =COUNTIFS(Ações!$C$6:$C$404,$A61,Ações!$A$6:$A$404,">="&'Por dia'!$R$5,Ações!$A$6:$A$404,"<="&'Por dia'!$S$5,Ações!$P$6:$P$404,"Atrasada") -> 0 | F61: =COUNTIFS(Ações!$C$6:$C$404,$A61,Ações!$A$6:$A$404,">="&'Por dia'!$R$5,Ações!$A$6:$A$404,"<="&'Por dia'!$S$5,Ações!$Q$6:$Q$404,"OK") -> 0 | G61: =COUNTIFS(Repercussão!$K$6:$K$304,$A61,Repercussão!$A$6:$A$304,">="&'Por dia'!$R$5,Repercussão!$A$6:$A$304,"<="&'Por dia'!$S$5) -> 0 | H61: =IF($D61=0,"",REPT("|",MIN(22,$D61)))
A62: =Listas!B16 -> Beatriz Holanda (Ícone) | B62: =COUNTIFS(Ações!$C$6:$C$404,$A62,Ações!$A$6:$A$404,">="&'Por dia'!$R$5,Ações!$A$6:$A$404,"<="&'Por dia'!$S$5) -> 0 | C62: =COUNTIFS(Ações!$C$6:$C$404,$A62,Ações!$A$6:$A$404,">="&'Por dia'!$R$5,Ações!$A$6:$A$404,"<="&'Por dia'!$S$5,Ações!$K$6:$K$404,"Em produção") -> 0 | D62: =COUNTIFS(Ações!$C$6:$C$404,$A62,Ações!$N$6:$N$404,">="&'Por dia'!$R$5,Ações!$N$6:$N$404,"<="&'Por dia'!$S$5,Ações!$O$6:$O$404,"Sim") -> 0 | E62: =COUNTIFS(Ações!$C$6:$C$404,$A62,Ações!$A$6:$A$404,">="&'Por dia'!$R$5,Ações!$A$6:$A$404,"<="&'Por dia'!$S$5,Ações!$P$6:$P$404,"Atrasada") -> 0 | F62: =COUNTIFS(Ações!$C$6:$C$404,$A62,Ações!$A$6:$A$404,">="&'Por dia'!$R$5,Ações!$A$6:$A$404,"<="&'Por dia'!$S$5,Ações!$Q$6:$Q$404,"OK") -> 0 | G62: =COUNTIFS(Repercussão!$K$6:$K$304,$A62,Repercussão!$A$6:$A$304,">="&'Por dia'!$R$5,Repercussão!$A$6:$A$304,"<="&'Por dia'!$S$5) -> 0 | H62: =IF($D62=0,"",REPT("|",MIN(22,$D62)))
... A68: =Listas!B22 -> Virgiane Rodrigues Passos (férias) | B68: =COUNTIFS(Ações!$C$6:$C$404,$A68,Ações!$A$6:$A$404,">="&'Por dia'!$R$5,Ações!$A$6:$A$404,"<="&'Por dia'!$S$5) -> 0 | C68: =COUNTIFS(Ações!$C$6:$C$404,$A68,Ações!$A$6:$A$404,">="&'Por dia'!$R$5,Ações!$A$6:$A$404,"<="&'Por dia'!$S$5,Ações!$K$6:$K$404,"Em produção") -> 0 | D68: =COUNTIFS(Ações!$C$6:$C$404,$A68,Ações!$N$6:$N$404,">="&'Por dia'!$R$5,Ações!$N$6:$N$404,"<="&'Por dia'!$S$5,Ações!$O$6:$O$404,"Sim") -> 0 | E68: =COUNTIFS(Ações!$C$6:$C$404,$A68,Ações!$A$6:$A$404,">="&'Por dia'!$R$5,Ações!$A$6:$A$404,"<="&'Por dia'!$S$5,Ações!$P$6:$P$404,"Atrasada") -> 0 | F68: =COUNTIFS(Ações!$C$6:$C$404,$A68,Ações!$A$6:$A$404,">="&'Por dia'!$R$5,Ações!$A$6:$A$404,"<="&'Por dia'!$S$5,Ações!$Q$6:$Q$404,"OK") -> 0 | G68: =COUNTIFS(Repercussão!$K$6:$K$304,$A68,Repercussão!$A$6:$A$304,">="&'Por dia'!$R$5,Repercussão!$A$6:$A$304,"<="&'Por dia'!$S$5) -> 0 | H68: =IF($D68=0,"",REPT("|",MIN(22,$D68)))
A69: TOTAL | B69: =SUM(B51:B68) -> 0 | C69: =SUM(C51:C68) -> 0 | D69: =SUM(D51:D68) -> 0 | E69: =SUM(E51:E68) -> 0 | F69: =SUM(F51:F68) -> 0 | G69: =SUM(G51:G68) -> 0
...

Sheet Listas
A1: LISTAS
A2: Acrescente itens nestas colunas e os menus das outras abas crescem sozinhos
A4: Squads | B4: Responsáveis | C4: Tipo de conteúdo | D4: SLA (dias) | E4: Audiovisual? | F4: Empresa / produtora | G4: Editor | H4: Marca | I4: Canal | J4: Status | K4: Libera (coordenação) | L4: Veículo | M4: Tipo de repercussão | N4: Tom | O4: Período do painel
A5: Litoral | B5: Luiz Fernando de Sousa Gonzaga | C5: Vídeo | D5: 3 | E5: Sim | F5: Equipe interna | G5: A definir | H5: Águas do Piauí | I5: Instagram | J5: Criação | K5: Cloves Costa | L5: Portal O Dia | M5: Matéria na imprensa | N5: Positiva | O5: Hoje
A6: Meio Norte | B6: Bruno (SA Propaganda) | C6: Spot | D6: 2 | E6: Sim | F6: SA Propaganda | H6: Águas de Teresina | I6: Facebook | J6: Em produção | K6: Pedro Santiago | L6: Portal AZ | M6: Replicação do material | N6: Neutra | O6: Ontem
A7: Cerrado | B7: Daniel Saturnino (Ícone) | C7: Testemunhal | D7: 4 | E7: Sim | F7: Conecta Piauí | H7: Águas de Timon | I7: WhatsApp | J7: Em aprovação | K7: Julia Pessoa | L7: Cidade Verde | M7: Citação da marca | N7: Negativa | O7: Últimos 7 dias
A8: Semiárido Norte | B8: Ana Isabel Monteiro de Sousa | C8: Nota / release | D8: 1 | E8: Não | F8: Ícone Comunicação | I8: Site institucional | J8: Concluído | L8: GP1 | M8: Entrevista | O8: Últimos 30 dias
A9: Semiárido Sul | B9: Ivana Machado Vasconcelos | C9: Card / arte | D9: 2 | E9: Não | F9: Produtora local | I9: Imprensa regional | J9: Stand-by | L9: Rádio local | M9: Post ou story de terceiro | O9: Este mês
A10: Águas de Teresina | B10: Phillipe Xadai (Conecta Piauí) | C10: Matéria / reportagem | D10: 3 | E10: Não | F10: Gráfica | I10: Rádio | L10: TV local | M10: Comentário em publicação | O10: Mês passado
B11: Maria Andreia Monteiro de Sousa | C11: Cobertura de obra | D11: 2 | E11: Sim | I11: TV | L11: Perfil no Instagram | M11: Outro | O11: Escolher datas
B12: Fernanda Messias de Carvalho | C12: Material impresso | D12: 5 | E12: Não | I12: Comunicação interna | O12: Tudo
B13: Leonardo Costa (Conecta Piauí) | I13: Carro de som
B14: Marta Soares Lima
B15: Thyago Felipe Alves da Costa
B16: Beatriz Holanda (Ícone)
B17: Marcio Messias dos Santos
B18: Thaynara Rakel Rodrigues Costa
B19: Laurel Ferreira (Ícone)
B20: Gabriela de Oliveira Santos Carvalho
B21: Isaac Haron (Ícone)
B22: Virgiane Rodrigues Passos (férias)
A66: Pode acrescentar linhas abaixo de cada coluna até a linha 64. Os menus pegam sozinhos.

Sheet Ações
A1: AÇÕES
A2: Uma linha por conteúdo. As colunas cinza se calculam sozinhas. Dá para digitar fora da lista.
A4: Data de cadastro | B4: Squad | C4: Responsável | D4: Tipo de conteúdo | E4: Empresa / produtora | F4: Editor responsável | G4: Marca | H4: Município | I4: Canal | J4: Título da ação | K4: Status | L4: Liberado por | M4: Prazo | N4: Concluída em | O4: Conta na meta | P4: Situação | Q4: Checklist | R4: Link do material (SharePoint) | S4: Tamanho (MB) | T4: Observações | U4: Audiovisual?
A5: 46280 | B5: Litoral | C5: Luiz Fernando de Sousa Gonzaga | D5: Vídeo | E5: SA Propaganda | F5: Bruno (SA Propaganda) | G5: Águas do Piauí | H5: Parnaíba | I5: Instagram | J5: Vídeo do avanço da obra de esgoto | K5: Em produção | M5: =IF(OR($A5="",$D5=""),"",$A5+IFERROR(INDEX(Listas!$D$5:$D$64,MATCH($D5,Listas!$C$5:$C$64,0)),3)) -> 46283 | O5: =IF($A5="","",IF($K5="Concluído","Sim","Não")) -> Não | P5: =IF($A5="","",IF($K5="Stand-by","Stand-by",IF($K5="Concluído","Concluída",IF(AND($M5<>"",$M5<TODAY()),"Atrasada","Em dia")))) -> Em dia | Q5: =IF($A5="","",IF(LEN(IF($J5="","título, ","")&IF($C5="","responsável, ","")&IF($D5="","tipo, ","")&IF($I5="","canal, ","")&IF($H5="","município, ","")&IF(AND($U5="Sim",$E5=""),"empresa, ","")&IF(AND($U5="Sim",$F5=""),"editor, ","")&IF(AND($K5="Concluído",$N5=""),"data de conclusão, ","")&IF(AND($K5="Concluído",$R5=""),"link, ","")&IF(AND($K5="Concluído",$L5=""),"quem liberou, ",""))=0,"OK","Falta "&LEFT(IF($J5="","título, ","")&IF($C5="","responsável, ","")&IF($D5="","tipo, ","")&IF($I5="","canal, ","")&IF($H5="","município, ","")&IF(AND($U5="Sim",$E5=""),"empresa, ","")&IF(AND($U5="Sim",$F5=""),"editor, ","")&IF(AND($K5="Concluído",$N5=""),"data de conclusão, ","")&IF(AND($K5="Concluído",$R5=""),"link, ","")&IF(AND($K5="Concluído",$L5=""),"quem liberou, ",""),LEN(IF($J5="","título, ","")&IF($C5="","responsável, ","")&IF($D5="","tipo, ","")&IF($I5="","canal, ","")&IF($H5="","município, ","")&IF(AND($U5="Sim",$E5=""),"empresa, ","")&IF(AND($U5="Sim",$F5=""),"editor, ","")&IF(AND($K5="Concluído",$N5=""),"data de conclusão, ","")&IF(AND($K5="Concluído",$R5=""),"link, ","")&IF(AND($K5="Concluído",$L5=""),"quem liberou, ",""))-2))) -> OK | R5: https://aegea.sharepoint.com/... | S5: 28 | T5: exemplo de preenchimento | U5: =IF($A5="","",IFERROR(INDEX(Listas!$E$5:$E$64,MATCH($D5,Listas!$C$5:$C$64,0)),"Não")) -> Sim
M6: =IF(OR($A6="",$D6=""),"",$A6+IFERROR(INDEX(Listas!$D$5:$D$64,MATCH($D6,Listas!$C$5:$C$64,0)),3)) | O6: =IF($A6="","",IF($K6="Concluído","Sim","Não")) | P6: =IF($A6="","",IF($K6="Stand-by","Stand-by",IF($K6="Concluído","Concluída",IF(AND($M6<>"",$M6<TODAY()),"Atrasada","Em dia")))) | Q6: =IF($A6="","",IF(LEN(IF($J6="","título, ","")&IF($C6="","responsável, ","")&IF($D6="","tipo, ","")&IF($I6="","canal, ","")&IF($H6="","município, ","")&IF(AND($U6="Sim",$E6=""),"empresa, ","")&IF(AND($U6="Sim",$F6=""),"editor, ","")&IF(AND($K6="Concluído",$N6=""),"data de conclusão, ","")&IF(AND($K6="Concluído",$R6=""),"link, ","")&IF(AND($K6="Concluído",$L6=""),"quem liberou, ",""))=0,"OK","Falta "&LEFT(IF($J6="","título, ","")&IF($C6="","responsável, ","")&IF($D6="","tipo, ","")&IF($I6="","canal, ","")&IF($H6="","município, ","")&IF(AND($U6="Sim",$E6=""),"empresa, ","")&IF(AND($U6="Sim",$F6=""),"editor, ","")&IF(AND($K6="Concluído",$N6=""),"data de conclusão, ","")&IF(AND($K6="Concluído",$R6=""),"link, ","")&IF(AND($K6="Concluído",$L6=""),"quem liberou, ",""),LEN(IF($J6="","título, ","")&IF($C6="","responsável, ","")&IF($D6="","tipo, ","")&IF($I6="","canal, ","")&IF($H6="","município, ","")&IF(AND($U6="Sim",$E6=""),"empresa, ","")&IF(AND($U6="Sim",$F6=""),"editor, ","")&IF(AND($K6="Concluído",$N6=""),"data de conclusão, ","")&IF(AND($K6="Concluído",$R6=""),"link, ","")&IF(AND($K6="Concluído",$L6=""),"quem liberou, ",""))-2))) | U6: =IF($A6="","",IFERROR(INDEX(Listas!$E$5:$E$64,MATCH($D6,Listas!$C$5:$C$64,0)),"Não"))
M7: =IF(OR($A7="",$D7=""),"",$A7+IFERROR(INDEX(Listas!$D$5:$D$64,MATCH($D7,Listas!$C$5:$C$64,0)),3)) | O7: =IF($A7="","",IF($K7="Concluído","Sim","Não")) | P7: =IF($A7="","",IF($K7="Stand-by","Stand-by",IF($K7="Concluído","Concluída",IF(AND($M7<>"",$M7<TODAY()),"Atrasada","Em dia")))) | Q7: =IF($A7="","",IF(LEN(IF($J7="","título, ","")&IF($C7="","responsável, ","")&IF($D7="","tipo, ","")&IF($I7="","canal, ","")&IF($H7="","município, ","")&IF(AND($U7="Sim",$E7=""),"empresa, ","")&IF(AND($U7="Sim",$F7=""),"editor, ","")&IF(AND($K7="Concluído",$N7=""),"data de conclusão, ","")&IF(AND($K7="Concluído",$R7=""),"link, ","")&IF(AND($K7="Concluído",$L7=""),"quem liberou, ",""))=0,"OK","Falta "&LEFT(IF($J7="","título, ","")&IF($C7="","responsável, ","")&IF($D7="","tipo, ","")&IF($I7="","canal, ","")&IF($H7="","município, ","")&IF(AND($U7="Sim",$E7=""),"empresa, ","")&IF(AND($U7="Sim",$F7=""),"editor, ","")&IF(AND($K7="Concluído",$N7=""),"data de conclusão, ","")&IF(AND($K7="Concluído",$R7=""),"link, ","")&IF(AND($K7="Concluído",$L7=""),"quem liberou, ",""),LEN(IF($J7="","título, ","")&IF($C7="","responsável, ","")&IF($D7="","tipo, ","")&IF($I7="","canal, ","")&IF($H7="","município, ","")&IF(AND($U7="Sim",$E7=""),"empresa, ","")&IF(AND($U7="Sim",$F7=""),"editor, ","")&IF(AND($K7="Concluído",$N7=""),"data de conclusão, ","")&IF(AND($K7="Concluído",$R7=""),"link, ","")&IF(AND($K7="Concluído",$L7=""),"quem liberou, ",""))-2))) | U7: =IF($A7="","",IFERROR(INDEX(Listas!$E$5:$E$64,MATCH($D7,Listas!$C$5:$C$64,0)),"Não"))
M8: =IF(OR($A8="",$D8=""),"",$A8+IFERROR(INDEX(Listas!$D$5:$D$64,MATCH($D8,Listas!$C$5:$C$64,0)),3)) | O8: =IF($A8="","",IF($K8="Concluído","Sim","Não")) | P8: =IF($A8="","",IF($K8="Stand-by","Stand-by",IF($K8="Concluído","Concluída",IF(AND($M8<>"",$M8<TODAY()),"Atrasada","Em dia")))) | Q8: =IF($A8="","",IF(LEN(IF($J8="","título, ","")&IF($C8="","responsável, ","")&IF($D8="","tipo, ","")&IF($I8="","canal, ","")&IF($H8="","município, ","")&IF(AND($U8="Sim",$E8=""),"empresa, ","")&IF(AND($U8="Sim",$F8=""),"editor, ","")&IF(AND($K8="Concluído",$N8=""),"data de conclusão, ","")&IF(AND($K8="Concluído",$R8=""),"link, ","")&IF(AND($K8="Concluído",$L8=""),"quem liberou, ",""))=0,"OK","Falta "&LEFT(IF($J8="","título, ","")&IF($C8="","responsável, ","")&IF($D8="","tipo, ","")&IF($I8="","canal, ","")&IF($H8="","município, ","")&IF(AND($U8="Sim",$E8=""),"empresa, ","")&IF(AND($U8="Sim",$F8=""),"editor, ","")&IF(AND($K8="Concluído",$N8=""),"data de conclusão, ","")&IF(AND($K8="Concluído",$R8=""),"link, ","")&IF(AND($K8="Concluído",$L8=""),"quem liberou, ",""),LEN(IF($J8="","título, ","")&IF($C8="","responsável, ","")&IF($D8="","tipo, ","")&IF($I8="","canal, ","")&IF($H8="","município, ","")&IF(AND($U8="Sim",$E8=""),"empresa, ","")&IF(AND($U8="Sim",$F8=""),"editor, ","")&IF(AND($K8="Concluído",$N8=""),"data de conclusão, ","")&IF(AND($K8="Concluído",$R8=""),"link, ","")&IF(AND($K8="Concluído",$L8=""),"quem liberou, ",""))-2))) | U8: =IF($A8="","",IFERROR(INDEX(Listas!$E$5:$E$64,MATCH($D8,Listas!$C$5:$C$64,0)),"Não"))
M9: =IF(OR($A9="",$D9=""),"",$A9+IFERROR(INDEX(Listas!$D$5:$D$64,MATCH($D9,Listas!$C$5:$C$64,0)),3)) | O9: =IF($A9="","",IF($K9="Concluído","Sim","Não")) | P9: =IF($A9="","",IF($K9="Stand-by","Stand-by",IF($K9="Concluído","Concluída",IF(AND($M9<>"",$M9<TODAY()),"Atrasada","Em dia")))) | Q9: =IF($A9="","",IF(LEN(IF($J9="","título, ","")&IF($C9="","responsável, ","")&IF($D9="","tipo, ","")&IF($I9="","canal, ","")&IF($H9="","município, ","")&IF(AND($U9="Sim",$E9=""),"empresa, ","")&IF(AND($U9="Sim",$F9=""),"editor, ","")&IF(AND($K9="Concluído",$N9=""),"data de conclusão, ","")&IF(AND($K9="Concluído",$R9=""),"link, ","")&IF(AND($K9="Concluído",$L9=""),"quem liberou, ",""))=0,"OK","Falta "&LEFT(IF($J9="","título, ","")&IF($C9="","responsável, ","")&IF($D9="","tipo, ","")&IF($I9="","canal, ","")&IF($H9="","município, ","")&IF(AND($U9="Sim",$E9=""),"empresa, ","")&IF(AND($U9="Sim",$F9=""),"editor, ","")&IF(AND($K9="Concluído",$N9=""),"data de conclusão, ","")&IF(AND($K9="Concluído",$R9=""),"link, ","")&IF(AND($K9="Concluído",$L9=""),"quem liberou, ",""),LEN(IF($J9="","título, ","")&IF($C9="","responsável, ","")&IF($D9="","tipo, ","")&IF($I9="","canal, ","")&IF($H9="","município, ","")&IF(AND($U9="Sim",$E9=""),"empresa, ","")&IF(AND($U9="Sim",$F9=""),"editor, ","")&IF(AND($K9="Concluído",$N9=""),"data de conclusão, ","")&IF(AND($K9="Concluído",$R9=""),"link, ","")&IF(AND($K9="Concluído",$L9=""),"quem liberou, ",""))-2))) | U9: =IF($A9="","",IFERROR(INDEX(Listas!$E$5:$E$64,MATCH($D9,Listas!$C$5:$C$64,0)),"Não"))
M10: =IF(OR($A10="",$D10=""),"",$A10+IFERROR(INDEX(Listas!$D$5:$D$64,MATCH($D10,Listas!$C$5:$C$64,0)),3)) | O10: =IF($A10="","",IF($K10="Concluído","Sim","Não")) | P10: =IF($A10="","",IF($K10="Stand-by","Stand-by",IF($K10="Concluído","Concluída",IF(AND($M10<>"",$M10<TODAY()),"Atrasada","Em dia")))) | Q10: =IF($A10="","",IF(LEN(IF($J10="","título, ","")&IF($C10="","responsável, ","")&IF($D10="","tipo, ","")&IF($I10="","canal, ","")&IF($H10="","município, ","")&IF(AND($U10="Sim",$E10=""),"empresa, ","")&IF(AND($U10="Sim",$F10=""),"editor, ","")&IF(AND($K10="Concluído",$N10=""),"data de conclusão, ","")&IF(AND($K10="Concluído",$R10=""),"link, ","")&IF(AND($K10="Concluído",$L10=""),"quem liberou, ",""))=0,"OK","Falta "&LEFT(IF($J10="","título, ","")&IF($C10="","responsável, ","")&IF($D10="","tipo, ","")&IF($I10="","canal, ","")&IF($H10="","município, ","")&IF(AND($U10="Sim",$E10=""),"empresa, ","")&IF(AND($U10="Sim",$F10=""),"editor, ","")&IF(AND($K10="Concluído",$N10=""),"data de conclusão, ","")&IF(AND($K10="Concluído",$R10=""),"link, ","")&IF(AND($K10="Concluído",$L10=""),"quem liberou, ",""),LEN(IF($J10="","título, ","")&IF($C10="","responsável, ","")&IF($D10="","tipo, ","")&IF($I10="","canal, ","")&IF($H10="","município, ","")&IF(AND($U10="Sim",$E10=""),"empresa, ","")&IF(AND($U10="Sim",$F10=""),"editor, ","")&IF(AND($K10="Concluído",$N10=""),"data de conclusão, ","")&IF(AND($K10="Concluído",$R10=""),"link, ","")&IF(AND($K10="Concluído",$L10=""),"quem liberou, ",""))-2))) | U10: =IF($A10="","",IFERROR(INDEX(Listas!$E$5:$E$64,MATCH($D10,Listas!$C$5:$C$64,0)),"Não"))
M11: =IF(OR($A11="",$D11=""),"",$A11+IFERROR(INDEX(Listas!$D$5:$D$64,MATCH($D11,Listas!$C$5:$C$64,0)),3)) | O11: =IF($A11="","",IF($K11="Concluído","Sim","Não")) | P11: =IF($A11="","",IF($K11="Stand-by","Stand-by",IF($K11="Concluído","Concluída",IF(AND($M11<>"",$M11<TODAY()),"Atrasada","Em dia")))) | Q11: =IF($A11="","",IF(LEN(IF($J11="","título, ","")&IF($C11="","responsável, ","")&IF($D11="","tipo, ","")&IF($I11="","canal, ","")&IF($H11="","município, ","")&IF(AND($U11="Sim",$E11=""),"empresa, ","")&IF(AND($U11="Sim",$F11=""),"editor, ","")&IF(AND($K11="Concluído",$N11=""),"data de conclusão, ","")&IF(AND($K11="Concluído",$R11=""),"link, ","")&IF(AND($K11="Concluído",$L11=""),"quem liberou, ",""))=0,"OK","Falta "&LEFT(IF($J11="","título, ","")&IF($C11="","responsável, ","")&IF($D11="","tipo, ","")&IF($I11="","canal, ","")&IF($H11="","município, ","")&IF(AND($U11="Sim",$E11=""),"empresa, ","")&IF(AND($U11="Sim",$F11=""),"editor, ","")&IF(AND($K11="Concluído",$N11=""),"data de conclusão, ","")&IF(AND($K11="Concluído",$R11=""),"link, ","")&IF(AND($K11="Concluído",$L11=""),"quem liberou, ",""),LEN(IF($J11="","título, ","")&IF($C11="","responsável, ","")&IF($D11="","tipo, ","")&IF($I11="","canal, ","")&IF($H11="","município, ","")&IF(AND($U11="Sim",$E11=""),"empresa, ","")&IF(AND($U11="Sim",$F11=""),"editor, ","")&IF(AND($K11="Concluído",$N11=""),"data de conclusão, ","")&IF(AND($K11="Concluído",$R11=""),"link, ","")&IF(AND($K11="Concluído",$L11=""),"quem liberou, ",""))-2))) | U11: =IF($A11="","",IFERROR(INDEX(Listas!$E$5:$E$64,MATCH($D11,Listas!$C$5:$C$64,0)),"Não"))
M12: =IF(OR($A12="",$D12=""),"",$A12+IFERROR(INDEX(Listas!$D$5:$D$64,MATCH($D12,Listas!$C$5:$C$64,0)),3)) | O12: =IF($A12="","",IF($K12="Concluído","Sim","Não")) | P12: =IF($A12="","",IF($K12="Stand-by","Stand-by",IF($K12="Concluído","Concluída",IF(AND($M12<>"",$M12<TODAY()),"Atrasada","Em dia")))) | Q12: =IF($A12="","",IF(LEN(IF($J12="","título, ","")&IF($C12="","responsável, ","")&IF($D12="","tipo, ","")&IF($I12="","canal, ","")&IF($H12="","município, ","")&IF(AND($U12="Sim",$E12=""),"empresa, ","")&IF(AND($U12="Sim",$F12=""),"editor, ","")&IF(AND($K12="Concluído",$N12=""),"data de conclusão, ","")&IF(AND($K12="Concluído",$R12=""),"link, ","")&IF(AND($K12="Concluído",$L12=""),"quem liberou, ",""))=0,"OK","Falta "&LEFT(IF($J12="","título, ","")&IF($C12="","responsável, ","")&IF($D12="","tipo, ","")&IF($I12="","canal, ","")&IF($H12="","município, ","")&IF(AND($U12="Sim",$E12=""),"empresa, ","")&IF(AND($U12="Sim",$F12=""),"editor, ","")&IF(AND($K12="Concluído",$N12=""),"data de conclusão, ","")&IF(AND($K12="Concluído",$R12=""),"link, ","")&IF(AND($K12="Concluído",$L12=""),"quem liberou, ",""),LEN(IF($J12="","título, ","")&IF($C12="","responsável, ","")&IF($D12="","tipo, ","")&IF($I12="","canal, ","")&IF($H12="","município, ","")&IF(AND($U12="Sim",$E12=""),"empresa, ","")&IF(AND($U12="Sim",$F12=""),"editor, ","")&IF(AND($K12="Concluído",$N12=""),"data de conclusão, ","")&IF(AND($K12="Concluído",$R12=""),"link, ","")&IF(AND($K12="Concluído",$L12=""),"quem liberou, ",""))-2))) | U12: =IF($A12="","",IFERROR(INDEX(Listas!$E$5:$E$64,MATCH($D12,Listas!$C$5:$C$64,0)),"Não"))
M13: =IF(OR($A13="",$D13=""),"",$A13+IFERROR(INDEX(Listas!$D$5:$D$64,MATCH($D13,Listas!$C$5:$C$64,0)),3)) | O13: =IF($A13="","",IF($K13="Concluído","Sim","Não")) | P13: =IF($A13="","",IF($K13="Stand-by","Stand-by",IF($K13="Concluído","Concluída",IF(AND($M13<>"",$M13<TODAY()),"Atrasada","Em dia")))) | Q13: =IF($A13="","",IF(LEN(IF($J13="","título, ","")&IF($C13="","responsável, ","")&IF($D13="","tipo, ","")&IF($I13="","canal, ","")&IF($H13="","município, ","")&IF(AND($U13="Sim",$E13=""),"empresa, ","")&IF(AND($U13="Sim",$F13=""),"editor, ","")&IF(AND($K13="Concluído",$N13=""),"data de conclusão, ","")&IF(AND($K13="Concluído",$R13=""),"link, ","")&IF(AND($K13="Concluído",$L13=""),"quem liberou, ",""))=0,"OK","Falta "&LEFT(IF($J13="","título, ","")&IF($C13="","responsável, ","")&IF($D13="","tipo, ","")&IF($I13="","canal, ","")&IF($H13="","município, ","")&IF(AND($U13="Sim",$E13=""),"empresa, ","")&IF(AND($U13="Sim",$F13=""),"editor, ","")&IF(AND($K13="Concluído",$N13=""),"data de conclusão, ","")&IF(AND($K13="Concluído",$R13=""),"link, ","")&IF(AND($K13="Concluído",$L13=""),"quem liberou, ",""),LEN(IF($J13="","título, ","")&IF($C13="","responsável, ","")&IF($D13="","tipo, ","")&IF($I13="","canal, ","")&IF($H13="","município, ","")&IF(AND($U13="Sim",$E13=""),"empresa, ","")&IF(AND($U13="Sim",$F13=""),"editor, ","")&IF(AND($K13="Concluído",$N13=""),"data de conclusão, ","")&IF(AND($K13="Concluído",$R13=""),"link, ","")&IF(AND($K13="Concluído",$L13=""),"quem liberou, ",""))-2))) | U13: =IF($A13="","",IFERROR(INDEX(Listas!$E$5:$E$64,MATCH($D13,Listas!$C$5:$C$64,0)),"Não"))
M14: =IF(OR($A14="",$D14=""),"",$A14+IFERROR(INDEX(Listas!$D$5:$D$64,MATCH($D14,Listas!$C$5:$C$64,0)),3)) | O14: =IF($A14="","",IF($K14="Concluído","Sim","Não")) | P14: =IF($A14="","",IF($K14="Stand-by","Stand-by",IF($K14="Concluído","Concluída",IF(AND($M14<>"",$M14<TODAY()),"Atrasada","Em dia")))) | Q14: =IF($A14="","",IF(LEN(IF($J14="","título, ","")&IF($C14="","responsável, ","")&IF($D14="","tipo, ","")&IF($I14="","canal, ","")&IF($H14="","município, ","")&IF(AND($U14="Sim",$E14=""),"empresa, ","")&IF(AND($U14="Sim",$F14=""),"editor, ","")&IF(AND($K14="Concluído",$N14=""),"data de conclusão, ","")&IF(AND($K14="Concluído",$R14=""),"link, ","")&IF(AND($K14="Concluído",$L14=""),"quem liberou, ",""))=0,"OK","Falta "&LEFT(IF($J14="","título, ","")&IF($C14="","responsável, ","")&IF($D14="","tipo, ","")&IF($I14="","canal, ","")&IF($H14="","município, ","")&IF(AND($U14="Sim",$E14=""),"empresa, ","")&IF(AND($U14="Sim",$F14=""),"editor, ","")&IF(AND($K14="Concluído",$N14=""),"data de conclusão, ","")&IF(AND($K14="Concluído",$R14=""),"link, ","")&IF(AND($K14="Concluído",$L14=""),"quem liberou, ",""),LEN(IF($J14="","título, ","")&IF($C14="","responsável, ","")&IF($D14="","tipo, ","")&IF($I14="","canal, ","")&IF($H14="","município, ","")&IF(AND($U14="Sim",$E14=""),"empresa, ","")&IF(AND($U14="Sim",$F14=""),"editor, ","")&IF(AND($K14="Concluído",$N14=""),"data de conclusão, ","")&IF(AND($K14="Concluído",$R14=""),"link, ","")&IF(AND($K14="Concluído",$L14=""),"quem liberou, ",""))-2))) | U14: =IF($A14="","",IFERROR(INDEX(Listas!$E$5:$E$64,MATCH($D14,Listas!$C$5:$C$64,0)),"Não"))
M15: =IF(OR($A15="",$D15=""),"",$A15+IFERROR(INDEX(Listas!$D$5:$D$64,MATCH($D15,Listas!$C$5:$C$64,0)),3)) | O15: =IF($A15="","",IF($K15="Concluído","Sim","Não")) | P15: =IF($A15="","",IF($K15="Stand-by","Stand-by",IF($K15="Concluído","Concluída",IF(AND($M15<>"",$M15<TODAY()),"Atrasada","Em dia")))) | Q15: =IF($A15="","",IF(LEN(IF($J15="","título, ","")&IF($C15="","responsável, ","")&IF($D15="","tipo, ","")&IF($I15="","canal, ","")&IF($H15="","município, ","")&IF(AND($U15="Sim",$E15=""),"empresa, ","")&IF(AND($U15="Sim",$F15=""),"editor, ","")&IF(AND($K15="Concluído",$N15=""),"data de conclusão, ","")&IF(AND($K15="Concluído",$R15=""),"link, ","")&IF(AND($K15="Concluído",$L15=""),"quem liberou, ",""))=0,"OK","Falta "&LEFT(IF($J15="","título, ","")&IF($C15="","responsável, ","")&IF($D15="","tipo, ","")&IF($I15="","canal, ","")&IF($H15="","município, ","")&IF(AND($U15="Sim",$E15=""),"empresa, ","")&IF(AND($U15="Sim",$F15=""),"editor, ","")&IF(AND($K15="Concluído",$N15=""),"data de conclusão, ","")&IF(AND($K15="Concluído",$R15=""),"link, ","")&IF(AND($K15="Concluído",$L15=""),"quem liberou, ",""),LEN(IF($J15="","título, ","")&IF($C15="","responsável, ","")&IF($D15="","tipo, ","")&IF($I15="","canal, ","")&IF($H15="","município, ","")&IF(AND($U15="Sim",$E15=""),"empresa, ","")&IF(AND($U15="Sim",$F15=""),"editor, ","")&IF(AND($K15="Concluído",$N15=""),"data de conclusão, ","")&IF(AND($K15="Concluído",$R15=""),"link, ","")&IF(AND($K15="Concluído",$L15=""),"quem liberou, ",""))-2))) | U15: =IF($A15="","",IFERROR(INDEX(Listas!$E$5:$E$64,MATCH($D15,Listas!$C$5:$C$64,0)),"Não"))
M16: =IF(OR($A16="",$D16=""),"",$A16+IFERROR(INDEX(Listas!$D$5:$D$64,MATCH($D16,Listas!$C$5:$C$64,0)),3)) | O16: =IF($A16="","",IF($K16="Concluído","Sim","Não")) | P16: =IF($A16="","",IF($K16="Stand-by","Stand-by",IF($K16="Concluído","Concluída",IF(AND($M16<>"",$M16<TODAY()),"Atrasada","Em dia")))) | Q16: =IF($A16="","",IF(LEN(IF($J16="","título, ","")&IF($C16="","responsável, ","")&IF($D16="","tipo, ","")&IF($I16="","canal, ","")&IF($H16="","município, ","")&IF(AND($U16="Sim",$E16=""),"empresa, ","")&IF(AND($U16="Sim",$F16=""),"editor, ","")&IF(AND($K16="Concluído",$N16=""),"data de conclusão, ","")&IF(AND($K16="Concluído",$R16=""),"link, ","")&IF(AND($K16="Concluído",$L16=""),"quem liberou, ",""))=0,"OK","Falta "&LEFT(IF($J16="","título, ","")&IF($C16="","responsável, ","")&IF($D16="","tipo, ","")&IF($I16="","canal, ","")&IF($H16="","município, ","")&IF(AND($U16="Sim",$E16=""),"empresa, ","")&IF(AND($U16="Sim",$F16=""),"editor, ","")&IF(AND($K16="Concluído",$N16=""),"data de conclusão, ","")&IF(AND($K16="Concluído",$R16=""),"link, ","")&IF(AND($K16="Concluído",$L16=""),"quem liberou, ",""),LEN(IF($J16="","título, ","")&IF($C16="","responsável, ","")&IF($D16="","tipo, ","")&IF($I16="","canal, ","")&IF($H16="","município, ","")&IF(AND($U16="Sim",$E16=""),"empresa, ","")&IF(AND($U16="Sim",$F16=""),"editor, ","")&IF(AND($K16="Concluído",$N16=""),"data de conclusão, ","")&IF(AND($K16="Concluído",$R16=""),"link, ","")&IF(AND($K16="Concluído",$L16=""),"quem liberou, ",""))-2))) | U16: =IF($A16="","",IFERROR(INDEX(Listas!$E$5:$E$64,MATCH($D16,Listas!$C$5:$C$64,0)),"Não"))
M17: =IF(OR($A17="",$D17=""),"",$A17+IFERROR(INDEX(Listas!$D$5:$D$64,MATCH($D17,Listas!$C$5:$C$64,0)),3)) | O17: =IF($A17="","",IF($K17="Concluído","Sim","Não")) | P17: =IF($A17="","",IF($K17="Stand-by","Stand-by",IF($K17="Concluído","Concluída",IF(AND($M17<>"",$M17<TODAY()),"Atrasada","Em dia")))) | Q17: =IF($A17="","",IF(LEN(IF($J17="","título, ","")&IF($C17="","responsável, ","")&IF($D17="","tipo, ","")&IF($I17="","canal, ","")&IF($H17="","município, ","")&IF(AND($U17="Sim",$E17=""),"empresa, ","")&IF(AND($U17="Sim",$F17=""),"editor, ","")&IF(AND($K17="Concluído",$N17=""),"data de conclusão, ","")&IF(AND($K17="Concluído",$R17=""),"link, ","")&IF(AND($K17="Concluído",$L17=""),"quem liberou, ",""))=0,"OK","Falta "&LEFT(IF($J17="","título, ","")&IF($C17="","responsável, ","")&IF($D17="","tipo, ","")&IF($I17="","canal, ","")&IF($H17="","município, ","")&IF(AND($U17="Sim",$E17=""),"empresa, ","")&IF(AND($U17="Sim",$F17=""),"editor, ","")&IF(AND($K17="Concluído",$N17=""),"data de conclusão, ","")&IF(AND($K17="Concluído",$R17=""),"link, ","")&IF(AND($K17="Concluído",$L17=""),"quem liberou, ",""),LEN(IF($J17="","título, ","")&IF($C17="","responsável, ","")&IF($D17="","tipo, ","")&IF($I17="","canal, ","")&IF($H17="","município, ","")&IF(AND($U17="Sim",$E17=""),"empresa, ","")&IF(AND($U17="Sim",$F17=""),"editor, ","")&IF(AND($K17="Concluído",$N17=""),"data de conclusão, ","")&IF(AND($K17="Concluído",$R17=""),"link, ","")&IF(AND($K17="Concluído",$L17=""),"quem liberou, ",""))-2))) | U17: =IF($A17="","",IFERROR(INDEX(Listas!$E$5:$E$64,MATCH($D17,Listas!$C$5:$C$64,0)),"Não"))
... M404: =IF(OR($A404="",$D404=""),"",$A404+IFERROR(INDEX(Listas!$D$5:$D$64,MATCH($D404,Listas!$C$5:$C$64,0)),3)) | O404: =IF($A404="","",IF($K404="Concluído","Sim","Não")) | P404: =IF($A404="","",IF($K404="Stand-by","Stand-by",IF($K404="Concluído","Concluída",IF(AND($M404<>"",$M404<TODAY()),"Atrasada","Em dia")))) | Q404: =IF($A404="","",IF(LEN(IF($J404="","título, ","")&IF($C404="","responsável, ","")&IF($D404="","tipo, ","")&IF($I404="","canal, ","")&IF($H404="","município, ","")&IF(AND($U404="Sim",$E404=""),"empresa, ","")&IF(AND($U404="Sim",$F404=""),"editor, ","")&IF(AND($K404="Concluído",$N404=""),"data de conclusão, ","")&IF(AND($K404="Concluído",$R404=""),"link, ","")&IF(AND($K404="Concluído",$L404=""),"quem liberou, ",""))=0,"OK","Falta "&LEFT(IF($J404="","título, ","")&IF($C404="","responsável, ","")&IF($D404="","tipo, ","")&IF($I404="","canal, ","")&IF($H404="","município, ","")&IF(AND($U404="Sim",$E404=""),"empresa, ","")&IF(AND($U404="Sim",$F404=""),"editor, ","")&IF(AND($K404="Concluído",$N404=""),"data de conclusão, ","")&IF(AND($K404="Concluído",$R404=""),"link, ","")&IF(AND($K404="Concluído",$L404=""),"quem liberou, ",""),LEN(IF($J404="","título, ","")&IF($C404="","responsável, ","")&IF($D404="","tipo, ","")&IF($I404="","canal, ","")&IF($H404="","município, ","")&IF(AND($U404="Sim",$E404=""),"empresa, ","")&IF(AND($U404="Sim",$F404=""),"editor, ","")&IF(AND($K404="Concluído",$N404=""),"data de conclusão, ","")&IF(AND($K404="Concluído",$R404=""),"link, ","")&IF(AND($K404="Concluído",$L404=""),"quem liberou, ",""))-2))) | U404: =IF($A404="","",IFERROR(INDEX(Listas!$E$5:$E$64,MATCH($D404,Listas!$C$5:$C$64,0)),"Não"))

Sheet Repercussão
A1: REPERCUSSÃO
A2: O retorno que o conteúdo gerou: matéria, replicação, citação, comentário.
A4: Data | B4: Squad | C4: Ação que gerou | D4: Veículo | E4: Tipo de repercussão | F4: Título da repercussão | G4: Alcance | H4: Interações | I4: Tom | J4: Link da publicação | K4: Quem registrou | L4: Checklist | M4: Observações
A5: 46280 | B5: Litoral | C5: Vídeo do avanço da obra de esgoto | D5: Portal O Dia | E5: Matéria na imprensa | F5: Portal publica matéria sobre o avanço da obra | G5: 3400 | H5: 120 | I5: Positiva | J5: https://... | K5: Luiz Fernando de Sousa Gonzaga | L5: =IF($A5="","",IF(LEN(IF($F5="","título, ","")&IF($D5="","veículo, ","")&IF($I5="","tom, ","")&IF($J5="","link, ","")&IF($G5="","alcance, ",""))=0,"OK","Falta "&LEFT(IF($F5="","título, ","")&IF($D5="","veículo, ","")&IF($I5="","tom, ","")&IF($J5="","link, ","")&IF($G5="","alcance, ",""),LEN(IF($F5="","título, ","")&IF($D5="","veículo, ","")&IF($I5="","tom, ","")&IF($J5="","link, ","")&IF($G5="","alcance, ",""))-2))) -> OK | M5: exemplo de preenchimento
L6: =IF($A6="","",IF(LEN(IF($F6="","título, ","")&IF($D6="","veículo, ","")&IF($I6="","tom, ","")&IF($J6="","link, ","")&IF($G6="","alcance, ",""))=0,"OK","Falta "&LEFT(IF($F6="","título, ","")&IF($D6="","veículo, ","")&IF($I6="","tom, ","")&IF($J6="","link, ","")&IF($G6="","alcance, ",""),LEN(IF($F6="","título, ","")&IF($D6="","veículo, ","")&IF($I6="","tom, ","")&IF($J6="","link, ","")&IF($G6="","alcance, ",""))-2)))
L7: =IF($A7="","",IF(LEN(IF($F7="","título, ","")&IF($D7="","veículo, ","")&IF($I7="","tom, ","")&IF($J7="","link, ","")&IF($G7="","alcance, ",""))=0,"OK","Falta "&LEFT(IF($F7="","título, ","")&IF($D7="","veículo, ","")&IF($I7="","tom, ","")&IF($J7="","link, ","")&IF($G7="","alcance, ",""),LEN(IF($F7="","título, ","")&IF($D7="","veículo, ","")&IF($I7="","tom, ","")&IF($J7="","link, ","")&IF($G7="","alcance, ",""))-2)))
L8: =IF($A8="","",IF(LEN(IF($F8="","título, ","")&IF($D8="","veículo, ","")&IF($I8="","tom, ","")&IF($J8="","link, ","")&IF($G8="","alcance, ",""))=0,"OK","Falta "&LEFT(IF($F8="","título, ","")&IF($D8="","veículo, ","")&IF($I8="","tom, ","")&IF($J8="","link, ","")&IF($G8="","alcance, ",""),LEN(IF($F8="","título, ","")&IF($D8="","veículo, ","")&IF($I8="","tom, ","")&IF($J8="","link, ","")&IF($G8="","alcance, ",""))-2)))
L9: =IF($A9="","",IF(LEN(IF($F9="","título, ","")&IF($D9="","veículo, ","")&IF($I9="","tom, ","")&IF($J9="","link, ","")&IF($G9="","alcance, ",""))=0,"OK","Falta "&LEFT(IF($F9="","título, ","")&IF($D9="","veículo, ","")&IF($I9="","tom, ","")&IF($J9="","link, ","")&IF($G9="","alcance, ",""),LEN(IF($F9="","título, ","")&IF($D9="","veículo, ","")&IF($I9="","tom, ","")&IF($J9="","link, ","")&IF($G9="","alcance, ",""))-2)))
L10: =IF($A10="","",IF(LEN(IF($F10="","título, ","")&IF($D10="","veículo, ","")&IF($I10="","tom, ","")&IF($J10="","link, ","")&IF($G10="","alcance, ",""))=0,"OK","Falta "&LEFT(IF($F10="","título, ","")&IF($D10="","veículo, ","")&IF($I10="","tom, ","")&IF($J10="","link, ","")&IF($G10="","alcance, ",""),LEN(IF($F10="","título, ","")&IF($D10="","veículo, ","")&IF($I10="","tom, ","")&IF($J10="","link, ","")&IF($G10="","alcance, ",""))-2)))
L11: =IF($A11="","",IF(LEN(IF($F11="","título, ","")&IF($D11="","veículo, ","")&IF($I11="","tom, ","")&IF($J11="","link, ","")&IF($G11="","alcance, ",""))=0,"OK","Falta "&LEFT(IF($F11="","título, ","")&IF($D11="","veículo, ","")&IF($I11="","tom, ","")&IF($J11="","link, ","")&IF($G11="","alcance, ",""),LEN(IF($F11="","título, ","")&IF($D11="","veículo, ","")&IF($I11="","tom, ","")&IF($J11="","link, ","")&IF($G11="","alcance, ",""))-2)))
L12: =IF($A12="","",IF(LEN(IF($F12="","título, ","")&IF($D12="","veículo, ","")&IF($I12="","tom, ","")&IF($J12="","link, ","")&IF($G12="","alcance, ",""))=0,"OK","Falta "&LEFT(IF($F12="","título, ","")&IF($D12="","veículo, ","")&IF($I12="","tom, ","")&IF($J12="","link, ","")&IF($G12="","alcance, ",""),LEN(IF($F12="","título, ","")&IF($D12="","veículo, ","")&IF($I12="","tom, ","")&IF($J12="","link, ","")&IF($G12="","alcance, ",""))-2)))
L13: =IF($A13="","",IF(LEN(IF($F13="","título, ","")&IF($D13="","veículo, ","")&IF($I13="","tom, ","")&IF($J13="","link, ","")&IF($G13="","alcance, ",""))=0,"OK","Falta "&LEFT(IF($F13="","título, ","")&IF($D13="","veículo, ","")&IF($I13="","tom, ","")&IF($J13="","link, ","")&IF($G13="","alcance, ",""),LEN(IF($F13="","título, ","")&IF($D13="","veículo, ","")&IF($I13="","tom, ","")&IF($J13="","link, ","")&IF($G13="","alcance, ",""))-2)))
L14: =IF($A14="","",IF(LEN(IF($F14="","título, ","")&IF($D14="","veículo, ","")&IF($I14="","tom, ","")&IF($J14="","link, ","")&IF($G14="","alcance, ",""))=0,"OK","Falta "&LEFT(IF($F14="","título, ","")&IF($D14="","veículo, ","")&IF($I14="","tom, ","")&IF($J14="","link, ","")&IF($G14="","alcance, ",""),LEN(IF($F14="","título, ","")&IF($D14="","veículo, ","")&IF($I14="","tom, ","")&IF($J14="","link, ","")&IF($G14="","alcance, ",""))-2)))
L15: =IF($A15="","",IF(LEN(IF($F15="","título, ","")&IF($D15="","veículo, ","")&IF($I15="","tom, ","")&IF($J15="","link, ","")&IF($G15="","alcance, ",""))=0,"OK","Falta "&LEFT(IF($F15="","título, ","")&IF($D15="","veículo, ","")&IF($I15="","tom, ","")&IF($J15="","link, ","")&IF($G15="","alcance, ",""),LEN(IF($F15="","título, ","")&IF($D15="","veículo, ","")&IF($I15="","tom, ","")&IF($J15="","link, ","")&IF($G15="","alcance, ",""))-2)))
L16: =IF($A16="","",IF(LEN(IF($F16="","título, ","")&IF($D16="","veículo, ","")&IF($I16="","tom, ","")&IF($J16="","link, ","")&IF($G16="","alcance, ",""))=0,"OK","Falta "&LEFT(IF($F16="","título, ","")&IF($D16="","veículo, ","")&IF($I16="","tom, ","")&IF($J16="","link, ","")&IF($G16="","alcance, ",""),LEN(IF($F16="","título, ","")&IF($D16="","veículo, ","")&IF($I16="","tom, ","")&IF($J16="","link, ","")&IF($G16="","alcance, ",""))-2)))
L17: =IF($A17="","",IF(LEN(IF($F17="","título, ","")&IF($D17="","veículo, ","")&IF($I17="","tom, ","")&IF($J17="","link, ","")&IF($G17="","alcance, ",""))=0,"OK","Falta "&LEFT(IF($F17="","título, ","")&IF($D17="","veículo, ","")&IF($I17="","tom, ","")&IF($J17="","link, ","")&IF($G17="","alcance, ",""),LEN(IF($F17="","título, ","")&IF($D17="","veículo, ","")&IF($I17="","tom, ","")&IF($J17="","link, ","")&IF($G17="","alcance, ",""))-2)))
... L304: =IF($A304="","",IF(LEN(IF($F304="","título, ","")&IF($D304="","veículo, ","")&IF($I304="","tom, ","")&IF($J304="","link, ","")&IF($G304="","alcance, ",""))=0,"OK","Falta "&LEFT(IF($F304="","título, ","")&IF($D304="","veículo, ","")&IF($I304="","tom, ","")&IF($J304="","link, ","")&IF($G304="","alcance, ",""),LEN(IF($F304="","título, ","")&IF($D304="","veículo, ","")&IF($I304="","tom, ","")&IF($J304="","link, ","")&IF($G304="","alcance, ",""))-2)))

Sheet Por dia
A1: POR DIA
A2: Quanto saiu em cada dia. A tabela anda sozinha com o calendário.
A4: Data | B4: Dia | C4: Concluídos | D4: Cadastrados | E4: Repercussões | F4: Meta do dia | G4: Atingiu? | I4: Por squad | J4: Concluídos | L4: Por analista | M4: Concluídos | O4: Por empresa | P4: Ações | R4: Período: de | S4: até
A5: =TODAY()-44 -> 46236 | B5: =TEXT($A5,"ddd") -> Sun | C5: =COUNTIFS(Ações!$N$6:$N$404,$A5,Ações!$O$6:$O$404,"Sim") -> 0 | D5: =COUNTIF(Ações!$A$6:$A$404,$A5) -> 0 | E5: =COUNTIF(Repercussão!$A$6:$A$304,$A5) -> 0 | F5: =Painel!$C$6 -> 60 | G5: =IF($C5>=$F5,"Sim","Não") -> Não | I5: =Listas!A5 -> Litoral | J5: =COUNTIFS(Ações!$B$6:$B$404,$I5,Ações!$N$6:$N$404,">="&$R$5,Ações!$N$6:$N$404,"<="&$S$5,Ações!$O$6:$O$404,"Sim") -> 0 | L5: =Listas!B5 -> Luiz Fernando de Sousa Gonzaga | M5: =COUNTIFS(Ações!$C$6:$C$404,$L5,Ações!$N$6:$N$404,">="&$R$5,Ações!$N$6:$N$404,"<="&$S$5,Ações!$O$6:$O$404,"Sim") -> 0 | O5: =Listas!F5 -> Equipe interna | P5: =COUNTIFS(Ações!$E$6:$E$404,$O5,Ações!$A$6:$A$404,">="&$R$5,Ações!$A$6:$A$404,"<="&$S$5) -> 0 | R5: =IF(Painel!$B$7="Hoje",TODAY(),IF(Painel!$B$7="Ontem",TODAY()-1,IF(Painel!$B$7="Últimos 7 dias",TODAY()-6,IF(Painel!$B$7="Últimos 30 dias",TODAY()-29,IF(Painel!$B$7="Este mês",DATE(YEAR(TODAY()),MONTH(TODAY()),1),IF(Painel!$B$7="Mês passado",DATE(YEAR(TODAY()),MONTH(TODAY())-1,1),IF(Painel!$B$7="Escolher datas",IF(Painel!$D$7="",DATE(2020,1,1),Painel!$D$7),DATE(2020,1,1)))))))) -> 46251 | S5: =IF(Painel!$B$7="Ontem",TODAY()-1,IF(Painel!$B$7="Mês passado",DATE(YEAR(TODAY()),MONTH(TODAY()),1)-1,IF(Painel!$B$7="Este mês",DATE(YEAR(TODAY()),MONTH(TODAY())+1,1)-1,IF(Painel!$B$7="Escolher datas",IF(Painel!$F$7="",DATE(2099,12,31),Painel!$F$7),IF(Painel!$B$7="Tudo",DATE(2099,12,31),TODAY()))))) -> 46280
A6: =TODAY()-43 -> 46237 | B6: =TEXT($A6,"ddd") -> Mon | C6: =COUNTIFS(Ações!$N$6:$N$404,$A6,Ações!$O$6:$O$404,"Sim") -> 0 | D6: =COUNTIF(Ações!$A$6:$A$404,$A6) -> 0 | E6: =COUNTIF(Repercussão!$A$6:$A$304,$A6) -> 0 | F6: =Painel!$C$6 -> 60 | G6: =IF($C6>=$F6,"Sim","Não") -> Não | I6: =Listas!A6 -> Meio Norte | J6: =COUNTIFS(Ações!$B$6:$B$404,$I6,Ações!$N$6:$N$404,">="&$R$5,Ações!$N$6:$N$404,"<="&$S$5,Ações!$O$6:$O$404,"Sim") -> 0 | L6: =Listas!B6 -> Bruno (SA Propaganda) | M6: =COUNTIFS(Ações!$C$6:$C$404,$L6,Ações!$N$6:$N$404,">="&$R$5,Ações!$N$6:$N$404,"<="&$S$5,Ações!$O$6:$O$404,"Sim") -> 0 | O6: =Listas!F6 -> SA Propaganda | P6: =COUNTIFS(Ações!$E$6:$E$404,$O6,Ações!$A$6:$A$404,">="&$R$5,Ações!$A$6:$A$404,"<="&$S$5) -> 0
A7: =TODAY()-42 -> 46238 | B7: =TEXT($A7,"ddd") -> Tue | C7: =COUNTIFS(Ações!$N$6:$N$404,$A7,Ações!$O$6:$O$404,"Sim") -> 0 | D7: =COUNTIF(Ações!$A$6:$A$404,$A7) -> 0 | E7: =COUNTIF(Repercussão!$A$6:$A$304,$A7) -> 0 | F7: =Painel!$C$6 -> 60 | G7: =IF($C7>=$F7,"Sim","Não") -> Não | I7: =Listas!A7 -> Cerrado | J7: =COUNTIFS(Ações!$B$6:$B$404,$I7,Ações!$N$6:$N$404,">="&$R$5,Ações!$N$6:$N$404,"<="&$S$5,Ações!$O$6:$O$404,"Sim") -> 0 | L7: =Listas!B7 -> Daniel Saturnino (Ícone) | M7: =COUNTIFS(Ações!$C$6:$C$404,$L7,Ações!$N$6:$N$404,">="&$R$5,Ações!$N$6:$N$404,"<="&$S$5,Ações!$O$6:$O$404,"Sim") -> 0 | O7: =Listas!F7 -> Conecta Piauí | P7: =COUNTIFS(Ações!$E$6:$E$404,$O7,Ações!$A$6:$A$404,">="&$R$5,Ações!$A$6:$A$404,"<="&$S$5) -> 0 | R7: Estas duas datas saem do filtro do Painel. Não precisa mexer aqui.
A8: =TODAY()-41 -> 46239 | B8: =TEXT($A8,"ddd") -> Wed | C8: =COUNTIFS(Ações!$N$6:$N$404,$A8,Ações!$O$6:$O$404,"Sim") -> 0 | D8: =COUNTIF(Ações!$A$6:$A$404,$A8) -> 0 | E8: =COUNTIF(Repercussão!$A$6:$A$304,$A8) -> 0 | F8: =Painel!$C$6 -> 60 | G8: =IF($C8>=$F8,"Sim","Não") -> Não | I8: =Listas!A8 -> Semiárido Norte | J8: =COUNTIFS(Ações!$B$6:$B$404,$I8,Ações!$N$6:$N$404,">="&$R$5,Ações!$N$6:$N$404,"<="&$S$5,Ações!$O$6:$O$404,"Sim") -> 0 | L8: =Listas!B8 -> Ana Isabel Monteiro de Sousa | M8: =COUNTIFS(Ações!$C$6:$C$404,$L8,Ações!$N$6:$N$404,">="&$R$5,Ações!$N$6:$N$404,"<="&$S$5,Ações!$O$6:$O$404,"Sim") -> 0 | O8: =Listas!F8 -> Ícone Comunicação | P8: =COUNTIFS(Ações!$E$6:$E$404,$O8,Ações!$A$6:$A$404,">="&$R$5,Ações!$A$6:$A$404,"<="&$S$5) -> 0
A9: =TODAY()-40 -> 46240 | B9: =TEXT($A9,"ddd") -> Thu | C9: =COUNTIFS(Ações!$N$6:$N$404,$A9,Ações!$O$6:$O$404,"Sim") -> 0 | D9: =COUNTIF(Ações!$A$6:$A$404,$A9) -> 0 | E9: =COUNTIF(Repercussão!$A$6:$A$304,$A9) -> 0 | F9: =Painel!$C$6 -> 60 | G9: =IF($C9>=$F9,"Sim","Não") -> Não | I9: =Listas!A9 -> Semiárido Sul | J9: =COUNTIFS(Ações!$B$6:$B$404,$I9,Ações!$N$6:$N$404,">="&$R$5,Ações!$N$6:$N$404,"<="&$S$5,Ações!$O$6:$O$404,"Sim") -> 0 | L9: =Listas!B9 -> Ivana Machado Vasconcelos | M9: =COUNTIFS(Ações!$C$6:$C$404,$L9,Ações!$N$6:$N$404,">="&$R$5,Ações!$N$6:$N$404,"<="&$S$5,Ações!$O$6:$O$404,"Sim") -> 0 | O9: =Listas!F9 -> Produtora local | P9: =COUNTIFS(Ações!$E$6:$E$404,$O9,Ações!$A$6:$A$404,">="&$R$5,Ações!$A$6:$A$404,"<="&$S$5) -> 0
A10: =TODAY()-39 -> 46241 | B10: =TEXT($A10,"ddd") -> Fri | C10: =COUNTIFS(Ações!$N$6:$N$404,$A10,Ações!$O$6:$O$404,"Sim") -> 0 | D10: =COUNTIF(Ações!$A$6:$A$404,$A10) -> 0 | E10: =COUNTIF(Repercussão!$A$6:$A$304,$A10) -> 0 | F10: =Painel!$C$6 -> 60 | G10: =IF($C10>=$F10,"Sim","Não") -> Não | I10: =Listas!A10 -> Águas de Teresina | J10: =COUNTIFS(Ações!$B$6:$B$404,$I10,Ações!$N$6:$N$404,">="&$R$5,Ações!$N$6:$N$404,"<="&$S$5,Ações!$O$6:$O$404,"Sim") -> 0 | L10: =Listas!B10 -> Phillipe Xadai (Conecta Piauí) | M10: =COUNTIFS(Ações!$C$6:$C$404,$L10,Ações!$N$6:$N$404,">="&$R$5,Ações!$N$6:$N$404,"<="&$S$5,Ações!$O$6:$O$404,"Sim") -> 0 | O10: =Listas!F10 -> Gráfica | P10: =COUNTIFS(Ações!$E$6:$E$404,$O10,Ações!$A$6:$A$404,">="&$R$5,Ações!$A$6:$A$404,"<="&$S$5) -> 0
